2025-06-08 21:01:14,328 - __main__ - INFO - Data cleaning completed successfully
2025-06-08 21:02:19,818 - __main__ - ERROR - Failed to generate data report: <matplotlib.backends.backend_mixed.MixedModeRenderer object at 0x000001FDB646E330>
2025-06-09 18:42:25,399 - __main__ - INFO - Data cleaning completed successfully
2025-06-12 19:01:53,090 - __main__ - INFO - Data cleaning completed successfully
2025-06-12 19:19:07,445 - __main__ - INFO - Data cleaning completed successfully
2025-06-13 17:18:38,069 - __main__ - INFO - Data cleaning completed successfully
2025-06-14 20:33:40,741 - __main__ - INFO - Data cleaning completed successfully
2025-06-14 22:56:34,961 - __main__ - INFO - Data cleaning completed successfully
2025-06-16 22:54:26,085 - root - ERROR - Error loading claims data: 'employee_id'
2025-06-16 22:55:32,985 - __main__ - INFO - Data cleaning completed successfully
2025-07-01 16:56:33,718 - __main__ - INFO - Data cleaning completed successfully
2025-07-01 16:57:21,055 - __main__ - INFO - Data cleaning completed successfully
2025-07-02 06:53:56,694 - __main__ - INFO - Data cleaning completed successfully
2025-07-02 08:48:57,562 - __main__ - INFO - Data cleaning completed successfully
2025-07-02 09:52:37,167 - __main__ - INFO - Data cleaning completed successfully
2025-07-02 10:11:50,601 - __main__ - INFO - Data cleaning completed successfully
2025-07-02 10:30:12,813 - __main__ - INFO - Data cleaning completed successfully
2025-07-02 10:59:25,796 - __main__ - INFO - Data cleaning completed successfully
2025-07-02 11:17:45,153 - __main__ - INFO - Data cleaning completed successfully
2025-07-02 11:58:00,151 - __main__ - INFO - Data cleaning completed successfully
2025-07-02 12:06:17,141 - __main__ - INFO - Data cleaning completed successfully
2025-07-02 12:09:23,238 - __main__ - INFO - Data cleaning completed successfully
2025-07-02 12:24:15,801 - __main__ - INFO - Data cleaning completed successfully
2025-07-02 13:05:14,322 - __main__ - INFO - Data cleaning completed successfully
2025-07-02 13:25:03,552 - __main__ - INFO - Data cleaning completed successfully
2025-07-02 14:13:53,382 - __main__ - INFO - Data cleaning completed successfully
2025-07-02 14:16:17,196 - __main__ - INFO - Data cleaning completed successfully
2025-07-02 14:23:39,081 - __main__ - INFO - Data cleaning completed successfully
2025-07-02 14:44:16,502 - __main__ - INFO - Data cleaning completed successfully
2025-07-02 15:44:41,536 - __main__ - INFO - Data cleaning completed successfully
2025-07-02 15:45:39,983 - __main__ - INFO - Data cleaning completed successfully
2025-07-02 17:48:16,594 - __main__ - INFO - Data cleaning completed successfully
2025-07-02 17:59:36,272 - __main__ - INFO - Data cleaning completed successfully
2025-07-02 18:02:27,727 - __main__ - INFO - Best params for GradientBoosting: {'regressor__n_estimators': 100, 'regressor__max_depth': 3, 'regressor__learning_rate': 0.01}
2025-07-02 18:02:27,769 - __main__ - WARNING - Fraud model training failed: This ColumnTransformer instance is not fitted yet. Call 'fit' with appropriate arguments before using this estimator.
2025-07-02 18:04:35,183 - root - ERROR - Report generation failed: Could not convert string '554479' to numeric
2025-07-02 18:09:59,528 - __main__ - INFO - Data cleaning completed successfully
2025-07-02 18:10:58,980 - root - ERROR - Report generation failed: Invalid binary data format: <class 'dict'>
2025-07-02 19:12:54,896 - __main__ - INFO - Data cleaning completed successfully
2025-07-02 19:19:22,779 - __main__ - INFO - Best params for GradientBoosting: {'regressor__n_estimators': 100, 'regressor__max_depth': 3, 'regressor__learning_rate': 0.01}
2025-07-02 19:19:31,463 - __main__ - INFO - Best params for RandomForest: {'regressor__n_estimators': 50, 'regressor__min_samples_split': 5, 'regressor__max_depth': 5}
2025-07-02 19:19:43,671 - __main__ - INFO - Best params for NeuralNetwork: {'regressor__solver': 'sgd', 'regressor__hidden_layer_sizes': (50,), 'regressor__activation': 'tanh'}
2025-07-02 19:29:02,456 - __main__ - INFO - Data cleaning completed successfully
2025-07-02 19:31:00,107 - __main__ - INFO - Best params for GradientBoosting: {'regressor__n_estimators': 100, 'regressor__max_depth': 3, 'regressor__learning_rate': 0.01}
2025-07-02 19:31:23,497 - __main__ - INFO - Best params for RandomForest: {'regressor__n_estimators': 50, 'regressor__min_samples_split': 5, 'regressor__max_depth': 5}
2025-07-02 19:32:35,992 - __main__ - INFO - Best params for NeuralNetwork: {'regressor__solver': 'sgd', 'regressor__hidden_layer_sizes': (50,), 'regressor__activation': 'tanh'}
2025-07-02 20:58:19,192 - __main__ - INFO - Data cleaning completed successfully
2025-07-03 04:50:35,352 - __main__ - INFO - Data cleaning completed successfully
2025-07-03 05:59:27,709 - __main__ - INFO - Data cleaning completed successfully
2025-07-03 07:04:16,639 - root - ERROR - File processing error: Unknown format code 'f' for object of type 'str'
2025-07-03 07:04:28,773 - __main__ - INFO - Data cleaning completed successfully
2025-07-03 07:12:06,590 - root - ERROR - File processing error: Unknown format code 'f' for object of type 'str'
2025-07-03 07:12:18,814 - __main__ - INFO - Data cleaning completed successfully
2025-07-03 07:16:39,949 - __main__ - INFO - Best params for GradientBoosting: {'regressor__n_estimators': 100, 'regressor__max_depth': 3, 'regressor__learning_rate': 0.01}
2025-07-03 07:16:39,995 - __main__ - WARNING - Fraud model training failed: This ColumnTransformer instance is not fitted yet. Call 'fit' with appropriate arguments before using this estimator.
2025-07-03 07:22:23,133 - root - ERROR - File processing error: Unknown format code 'f' for object of type 'str'
2025-07-03 07:22:30,379 - __main__ - INFO - Data cleaning completed successfully
2025-07-03 07:30:56,992 - root - ERROR - File processing error: Unknown format code 'f' for object of type 'str'
2025-07-03 07:34:40,837 - root - ERROR - File processing error: Unknown format code 'f' for object of type 'str'
2025-07-03 07:46:22,361 - root - ERROR - File processing error: Unknown format code 'f' for object of type 'str'
2025-07-03 07:46:52,594 - __main__ - INFO - Data cleaning completed successfully
2025-07-03 08:33:16,688 - root - ERROR - File processing error: Unknown format code 'f' for object of type 'str'
2025-07-03 08:33:28,669 - __main__ - INFO - Data cleaning completed successfully
2025-07-03 08:49:41,837 - root - ERROR - File processing error: Unknown format code 'f' for object of type 'str'
2025-07-03 08:49:49,344 - __main__ - INFO - Data cleaning completed successfully
2025-07-03 09:03:21,600 - root - ERROR - File processing error: Unknown format code 'f' for object of type 'str'
2025-07-03 09:17:12,185 - root - ERROR - File processing error: Unknown format code 'f' for object of type 'str'
2025-07-03 09:21:11,943 - root - ERROR - File processing error: Unknown format code 'f' for object of type 'str'
2025-07-03 10:46:06,360 - root - ERROR - Error loading claims data: Error tokenizing data. C error: Expected 2 fields in line 8, saw 3

2025-07-03 10:46:41,577 - root - ERROR - Error loading claims data: Error tokenizing data. C error: Expected 2 fields in line 8, saw 3

2025-07-03 10:47:44,036 - root - ERROR - Error loading claims data: Error tokenizing data. C error: Expected 2 fields in line 8, saw 3

2025-07-03 10:51:26,907 - root - ERROR - Error loading claims data: Error tokenizing data. C error: Expected 2 fields in line 8, saw 3

2025-07-03 10:54:44,852 - root - ERROR - Error loading claims data: Error tokenizing data. C error: Expected 2 fields in line 8, saw 3

2025-07-03 11:08:00,036 - root - ERROR - Error loading claims data: Error tokenizing data. C error: Expected 2 fields in line 8, saw 3

2025-07-03 11:08:22,468 - root - ERROR - File processing error: Unknown format code 'f' for object of type 'str'
2025-07-03 11:11:23,393 - root - ERROR - Data loading failed
Traceback (most recent call last):
  File "C:\Users\dkeya\Documents\projects\the Verse\demo\app.py", line 1585, in load_real_claims_data
    df = pd.read_csv(uploaded_file, thousands=',', encoding=encoding)
         ^^^^^^^^^^^^^^^^^^^^^^^^^^^^^^^^^^^^^^^^^^^^^^^^^^^^^^^^^^^^
  File "C:\Users\dkeya\AppData\Local\Packages\PythonSoftwareFoundation.Python.3.12_qbz5n2kfra8p0\LocalCache\local-packages\Python312\site-packages\pandas\io\parsers\readers.py", line 1026, in read_csv
    return _read(filepath_or_buffer, kwds)
           ^^^^^^^^^^^^^^^^^^^^^^^^^^^^^^^
  File "C:\Users\dkeya\AppData\Local\Packages\PythonSoftwareFoundation.Python.3.12_qbz5n2kfra8p0\LocalCache\local-packages\Python312\site-packages\pandas\io\parsers\readers.py", line 620, in _read
    parser = TextFileReader(filepath_or_buffer, **kwds)
             ^^^^^^^^^^^^^^^^^^^^^^^^^^^^^^^^^^^^^^^^^^
  File "C:\Users\dkeya\AppData\Local\Packages\PythonSoftwareFoundation.Python.3.12_qbz5n2kfra8p0\LocalCache\local-packages\Python312\site-packages\pandas\io\parsers\readers.py", line 1620, in __init__
    self._engine = self._make_engine(f, self.engine)
                   ^^^^^^^^^^^^^^^^^^^^^^^^^^^^^^^^^
  File "C:\Users\dkeya\AppData\Local\Packages\PythonSoftwareFoundation.Python.3.12_qbz5n2kfra8p0\LocalCache\local-packages\Python312\site-packages\pandas\io\parsers\readers.py", line 1898, in _make_engine
    return mapping[engine](f, **self.options)
           ^^^^^^^^^^^^^^^^^^^^^^^^^^^^^^^^^^
  File "C:\Users\dkeya\AppData\Local\Packages\PythonSoftwareFoundation.Python.3.12_qbz5n2kfra8p0\LocalCache\local-packages\Python312\site-packages\pandas\io\parsers\c_parser_wrapper.py", line 93, in __init__
    self._reader = parsers.TextReader(src, **kwds)
                   ^^^^^^^^^^^^^^^^^^^^^^^^^^^^^^^
  File "parsers.pyx", line 581, in pandas._libs.parsers.TextReader.__cinit__
pandas.errors.EmptyDataError: No columns to parse from file
2025-07-03 11:11:35,374 - root - ERROR - Data loading failed
Traceback (most recent call last):
  File "C:\Users\dkeya\Documents\projects\the Verse\demo\app.py", line 1585, in load_real_claims_data
    df = pd.read_csv(uploaded_file, thousands=',', encoding=encoding)
         ^^^^^^^^^^^^^^^^^^^^^^^^^^^^^^^^^^^^^^^^^^^^^^^^^^^^^^^^^^^^
  File "C:\Users\dkeya\AppData\Local\Packages\PythonSoftwareFoundation.Python.3.12_qbz5n2kfra8p0\LocalCache\local-packages\Python312\site-packages\pandas\io\parsers\readers.py", line 1026, in read_csv
    return _read(filepath_or_buffer, kwds)
           ^^^^^^^^^^^^^^^^^^^^^^^^^^^^^^^
  File "C:\Users\dkeya\AppData\Local\Packages\PythonSoftwareFoundation.Python.3.12_qbz5n2kfra8p0\LocalCache\local-packages\Python312\site-packages\pandas\io\parsers\readers.py", line 620, in _read
    parser = TextFileReader(filepath_or_buffer, **kwds)
             ^^^^^^^^^^^^^^^^^^^^^^^^^^^^^^^^^^^^^^^^^^
  File "C:\Users\dkeya\AppData\Local\Packages\PythonSoftwareFoundation.Python.3.12_qbz5n2kfra8p0\LocalCache\local-packages\Python312\site-packages\pandas\io\parsers\readers.py", line 1620, in __init__
    self._engine = self._make_engine(f, self.engine)
                   ^^^^^^^^^^^^^^^^^^^^^^^^^^^^^^^^^
  File "C:\Users\dkeya\AppData\Local\Packages\PythonSoftwareFoundation.Python.3.12_qbz5n2kfra8p0\LocalCache\local-packages\Python312\site-packages\pandas\io\parsers\readers.py", line 1898, in _make_engine
    return mapping[engine](f, **self.options)
           ^^^^^^^^^^^^^^^^^^^^^^^^^^^^^^^^^^
  File "C:\Users\dkeya\AppData\Local\Packages\PythonSoftwareFoundation.Python.3.12_qbz5n2kfra8p0\LocalCache\local-packages\Python312\site-packages\pandas\io\parsers\c_parser_wrapper.py", line 93, in __init__
    self._reader = parsers.TextReader(src, **kwds)
                   ^^^^^^^^^^^^^^^^^^^^^^^^^^^^^^^
  File "parsers.pyx", line 581, in pandas._libs.parsers.TextReader.__cinit__
pandas.errors.EmptyDataError: No columns to parse from file
2025-07-03 11:19:35,103 - root - ERROR - File processing error: 'utf-8' codec can't decode bytes in position 15-16: invalid continuation byte
2025-07-03 11:20:41,308 - root - ERROR - File processing error: 'utf-8' codec can't decode bytes in position 15-16: invalid continuation byte
2025-07-03 11:25:29,365 - root - INFO - Renamed PROV_NAME to provider_id
2025-07-03 11:25:29,367 - root - INFO - Renamed AMOUNT to amount
2025-07-03 11:25:29,368 - root - INFO - Renamed CLAIM_PROV_DATE to date
2025-07-03 11:25:29,368 - root - INFO - Renamed CLAIM_MEMBER_NUMBER to employee_id
2025-07-03 11:25:29,368 - root - INFO - Renamed Ailment to diagnosis
2025-07-03 11:25:29,368 - root - INFO - Renamed SERVICE_DESCRIPTION to treatment
2025-07-03 11:25:29,368 - root - INFO - Renamed POL_NAME to employer
2025-07-03 11:25:29,368 - root - INFO - Renamed Department to department
2025-07-03 11:25:41,359 - __main__ - INFO - Data cleaning completed successfully
2025-07-03 11:32:31,491 - root - INFO - Renamed PROV_NAME to provider_id
2025-07-03 11:32:31,494 - root - INFO - Renamed AMOUNT to amount
2025-07-03 11:32:31,494 - root - INFO - Renamed CLAIM_PROV_DATE to date
2025-07-03 11:32:31,494 - root - INFO - Renamed CLAIM_MEMBER_NUMBER to employee_id
2025-07-03 11:32:31,494 - root - INFO - Renamed Ailment to diagnosis
2025-07-03 11:32:31,500 - root - INFO - Renamed SERVICE_DESCRIPTION to treatment
2025-07-03 11:32:31,500 - root - INFO - Renamed POL_NAME to employer
2025-07-03 11:32:31,504 - root - INFO - Renamed Department to department
2025-07-03 11:33:04,143 - __main__ - INFO - Data cleaning completed successfully
